Initial State:  os.statvfs_result(f_bsize=4096, f_frsize=4096, f_blocks=4096, f_bfree=3045, 
                f_bavail=3045, f_files=128, f_ffree=123, f_favail=123, f_flag=4102, f_namemax=252)
Final State:    os.statvfs_result(f_bsize=4096, f_frsize=4096, f_blocks=4096, f_bfree=3036, 
                f_bavail=3036, f_files=128, f_ffree=123, f_favail=123, f_flag=4102, f_namemax=252)
Points:
	4/4 - stat st_size matches requested size 32768
	1/1 - stat st_mtime updated
Traceback (most recent call last):
  File "/h/u2/csc369h/fall/pub/a4/testing/scripts/submission.py", line 242, in _run
    self.unmount(abort=timeout_exc is not None, cwd=unmount_cwd)
  File "/h/u2/csc369h/fall/pub/a4/testing/scripts/submission.py", line 210, in unmount
    wait_or_kill(self.vsfs_proc, check=check, timeout=10,
  File "/h/u2/csc369h/fall/pub/a4/testing/scripts/util.py", line 66, in wait_or_kill
    raise exception_chain(subprocess.CalledProcessError(ret, proc.args,
subprocess.CalledProcessError: Command '['./vsfs', '/h/u15/c1/00/liuzexi3/liuzexi3/A4/testdir/_img_', '/tmp/liuzexi3-vsfstest', '-f', '-d']' died with <Signals.SIGSEGV: 11>.

The above exception was the direct cause of the following exception:

Traceback (most recent call last):
  File "/h/u2/csc369h/fall/pub/a4/testing/scripts/test.py", line 28, in run_test
    test_function(submission, log)
  File "/h/u2/csc369h/fall/pub/a4/testing/scripts/tests.py", line 752, in test
    s.run(grow, timeout=5)
  File "/h/u2/csc369h/fall/pub/a4/testing/scripts/submission.py", line 312, in run
    return self._run(timeout, cwd, fn, *args, **kwargs)
  File "/h/u2/csc369h/fall/pub/a4/testing/scripts/submission.py", line 247, in _run
    raise exception_chain(fn_exc, vsfs_exc, timeout_exc)
  File "/h/u2/csc369h/fall/pub/a4/testing/scripts/submission.py", line 235, in _run
    return future.result(timeout)
  File "/local/packages/python-3.10/lib/python3.10/concurrent/futures/_base.py", line 458, in result
    return self.__get_result()
  File "/local/packages/python-3.10/lib/python3.10/concurrent/futures/_base.py", line 403, in __get_result
    raise self._exception
  File "/local/packages/python-3.10/lib/python3.10/concurrent/futures/thread.py", line 58, in run
    result = self.fn(*self.args, **self.kwargs)
  File "/h/u2/csc369h/fall/pub/a4/testing/scripts/tests.py", line 734, in grow
    with open(fname,'rb') as f:
OSError: [Errno 107] Transport endpoint is not connected

