Initial State:  os.statvfs_result(f_bsize=4096, f_frsize=4096, f_blocks=256, f_bfree=248, 
                f_bavail=248, f_files=256, f_ffree=255, f_favail=255, f_flag=4102, f_namemax=252)
Traceback (most recent call last):
  File "/h/u2/csc369h/fall/pub/a4/testing/scripts/test.py", line 28, in run_test
    test_function(submission, log)
  File "/h/u2/csc369h/fall/pub/a4/testing/scripts/tests.py", line 529, in test
    s.run(fn, timeout=5)
  File "/h/u2/csc369h/fall/pub/a4/testing/scripts/submission.py", line 312, in run
    return self._run(timeout, cwd, fn, *args, **kwargs)
  File "/h/u2/csc369h/fall/pub/a4/testing/scripts/submission.py", line 247, in _run
    raise exception_chain(fn_exc, vsfs_exc, timeout_exc)
  File "/h/u2/csc369h/fall/pub/a4/testing/scripts/submission.py", line 235, in _run
    return future.result(timeout)
  File "/local/packages/python-3.10/lib/python3.10/concurrent/futures/_base.py", line 458, in result
    return self.__get_result()
  File "/local/packages/python-3.10/lib/python3.10/concurrent/futures/_base.py", line 403, in __get_result
    raise self._exception
  File "/local/packages/python-3.10/lib/python3.10/concurrent/futures/thread.py", line 58, in run
    result = self.fn(*self.args, **self.kwargs)
  File "/h/u2/csc369h/fall/pub/a4/testing/scripts/tests.py", line 506, in fn
    raise e
  File "/h/u2/csc369h/fall/pub/a4/testing/scripts/tests.py", line 500, in fn
    Path(fname).touch()
  File "/local/packages/python-3.10/lib/python3.10/pathlib.py", line 1168, in touch
    self._accessor.touch(self, mode, exist_ok)
  File "/local/packages/python-3.10/lib/python3.10/pathlib.py", line 331, in touch
    fd = os.open(path, flags, mode)
OSError: [Errno 28] No space left on device: 'file.14'

